<?xml version="1.0" ?>
<!-- =================================================================================== -->
<!-- |    This document was autogenerated by xacro from bipedal_robot.urdf.xacro       | -->
<!-- |    EDITING THIS FILE BY HAND IS NOT RECOMMENDED                                 | -->
<!-- =================================================================================== -->
<robot name="bipedal_robot">
  <!-- This file is not a robot in and of itself, it just contains some useful tags that could be included in any robot -->
  <!-- Specify some colours -->
  <material name="white">
    <color rgba="1 1 1 1"/>
  </material>
  <material name="orange">
    <color rgba="1 0.3 0.1 1"/>
  </material>
  <material name="blue">
    <color rgba="0.2 0.2 1 1"/>
  </material>
  <material name="red">
    <color rgba="1 0.2 0.2 1"/>
  </material>
  <!-- Specify some standard inertial calculations https://en.wikipedia.org/wiki/List_of_moments_of_inertia -->
  <!-- These make use of xacro's mathematical functionality -->
  <!--*** Define Properties ***-->
  <!--*** Define Macros ***-->
  <!-- Initializing Macro -->
  <!-- Links -->
  <!-- World -->
  <link name="world"/>
  <link name="base_link">
    <visual>
      <origin rpy="0 0 0" xyz="0 0 0"/>
      <geometry>
        <box size="0.2 0.4 0.1"/>
      </geometry>
      <material name="white"/>
    </visual>
    <collision>
      <origin rpy="0 0 0" xyz="0 0 0"/>
      <geometry>
        <box size="0.2 0.4 0.1"/>
      </geometry>
    </collision>
    <inertial>
      <origin rpy="0 0 0" xyz="0 0 0"/>
      <mass value="17.6"/>
      <inertia ixx="0.2493333333333334" ixy="0.0" ixz="0.0" iyy="0.07333333333333335" iyz="0.0" izz="0.2933333333333334"/>
    </inertial>
  </link>
  <link name="right_upper_leg_link">
    <visual>
      <origin rpy="0 0 0" xyz="0 0 -0.09999999999999999"/>
      <geometry>
        <box size="0.08 0.05 0.3"/>
      </geometry>
      <material name="orange"/>
    </visual>
    <collision>
      <origin rpy="0 0 0" xyz="0 0 -0.09999999999999999"/>
      <geometry>
        <box size="0.08 0.05 0.3"/>
      </geometry>
    </collision>
    <inertial>
      <origin rpy="0 0 0" xyz="0 0 -0.09999999999999999"/>
      <mass value="1.4"/>
      <inertia ixx="0.010791666666666665" ixy="0.0" ixz="0.0" iyy="0.011246666666666665" iyz="0.0" izz="0.0010383333333333334"/>
    </inertial>
  </link>
  <link name="right_lower_leg_link">
    <visual>
      <origin rpy="0 0 0" xyz="0 0 -0.09999999999999999"/>
      <geometry>
        <box size="0.08 0.05 0.3"/>
      </geometry>
      <material name="orange"/>
    </visual>
    <collision>
      <origin rpy="0 0 0" xyz="0 0 -0.09999999999999999"/>
      <geometry>
        <box size="0.08 0.05 0.3"/>
      </geometry>
    </collision>
    <inertial>
      <origin rpy="0 0 0" xyz="0 0 -0.09999999999999999"/>
      <mass value="1.4"/>
      <inertia ixx="0.010791666666666665" ixy="0.0" ixz="0.0" iyy="0.011246666666666665" iyz="0.0" izz="0.0010383333333333334"/>
    </inertial>
  </link>
  <link name="right_wheel_link">
    <visual>
      <origin rpy="0 0 0" xyz="0 0 0"/>
      <geometry>
        <cylinder length="0.05" radius="0.1"/>
      </geometry>
      <material name="blue"/>
    </visual>
    <collision>
      <origin rpy="0 0 0" xyz="0 0 0"/>
      <geometry>
        <cylinder length="0.05" radius="0.1"/>
      </geometry>
    </collision>
    <inertial>
      <origin rpy="0 0 0" xyz="0 0 0"/>
      <mass value="2.24"/>
      <inertia ixx="0.006066666666666668" ixy="0.0" ixz="0.0" iyy="0.006066666666666668" iyz="0.0" izz="0.011200000000000003"/>
    </inertial>
  </link>
  <link name="left_upper_leg_link">
    <visual>
      <origin rpy="0 0 0" xyz="0 0 -0.09999999999999999"/>
      <geometry>
        <box size="0.08 0.05 0.3"/>
      </geometry>
      <material name="orange"/>
    </visual>
    <collision>
      <origin rpy="0 0 0" xyz="0 0 -0.09999999999999999"/>
      <geometry>
        <box size="0.08 0.05 0.3"/>
      </geometry>
    </collision>
    <inertial>
      <origin rpy="0 0 0" xyz="0 0 -0.09999999999999999"/>
      <mass value="1.4"/>
      <inertia ixx="0.010791666666666665" ixy="0.0" ixz="0.0" iyy="0.011246666666666665" iyz="0.0" izz="0.0010383333333333334"/>
    </inertial>
  </link>
  <link name="left_lower_leg_link">
    <visual>
      <origin rpy="0 0 0" xyz="0 0 -0.09999999999999999"/>
      <geometry>
        <box size="0.08 0.05 0.3"/>
      </geometry>
      <material name="orange"/>
    </visual>
    <collision>
      <origin rpy="0 0 0" xyz="0 0 -0.09999999999999999"/>
      <geometry>
        <box size="0.08 0.05 0.3"/>
      </geometry>
    </collision>
    <inertial>
      <origin rpy="0 0 0" xyz="0 0 -0.09999999999999999"/>
      <mass value="1.4"/>
      <inertia ixx="0.010791666666666665" ixy="0.0" ixz="0.0" iyy="0.011246666666666665" iyz="0.0" izz="0.0010383333333333334"/>
    </inertial>
  </link>
  <link name="left_wheel_link">
    <visual>
      <origin rpy="0 0 0" xyz="0 0 0"/>
      <geometry>
        <cylinder length="0.05" radius="0.1"/>
      </geometry>
      <material name="blue"/>
    </visual>
    <collision>
      <origin rpy="0 0 0" xyz="0 0 0"/>
      <geometry>
        <cylinder length="0.05" radius="0.1"/>
      </geometry>
    </collision>
    <inertial>
      <origin rpy="0 0 0" xyz="0 0 0"/>
      <mass value="2.24"/>
      <inertia ixx="0.006066666666666668" ixy="0.0" ixz="0.0" iyy="0.006066666666666668" iyz="0.0" izz="0.011200000000000003"/>
    </inertial>
  </link>
  <!-- IMU -->
  <link name="IMU_link">
    <inertial>
      <mass value="0.001"/>
      <origin rpy="0 0 0" xyz="0 0 0"/>
      <inertia ixx="0.0001" ixy="0" ixz="0" iyy="0.000001" iyz="0" izz="0.0001"/>
    </inertial>
    <visual>
      <origin rpy="0 0 0" xyz="0 0 0"/>
      <geometry>
        <box size="0.01 0.01 0.01"/>
      </geometry>
      <material name="red"/>
    </visual>
    <collision>
      <origin rpy="0 0 0" xyz="0 0 0"/>
      <geometry>
        <box size=".01 .01 .01"/>
      </geometry>
    </collision>
  </link>
  <!-- Joints -->
  <!-- World -->
  <joint name="base_joint" type="floating">
    <origin rpy="0 0 0" xyz="0 0 1"/>
    <parent link="world"/>
    <child link="base_link"/>
  </joint>
  <joint name="hip_right_joint" type="revolute">
    <parent link="base_link"/>
    <child link="right_upper_leg_link"/>
    <origin rpy="0 0 0" xyz="0 0.225 0"/>
    <axis xyz="0 1 0"/>
    <limit effort="10" lower="-1.57" upper="1.57" velocity="100"/>
    <dynamics damping="0.1" friction="0.1"/>
  </joint>
  <joint name="hip_left_joint" type="revolute">
    <parent link="base_link"/>
    <child link="left_upper_leg_link"/>
    <origin rpy="0 0 0" xyz="0 -0.225 0"/>
    <axis xyz="0 1 0"/>
    <limit effort="10" lower="-1.57" upper="1.57" velocity="100"/>
    <dynamics damping="0.1" friction="0.1"/>
  </joint>
  <joint name="knee_right_joint" type="revolute">
    <parent link="right_upper_leg_link"/>
    <child link="right_lower_leg_link"/>
    <origin rpy="0 0 0" xyz="0 0.05 -0.21"/>
    <axis xyz="0 1 0"/>
    <limit effort="10" lower="-1.57" upper="1.57" velocity="100"/>
    <dynamics damping="0.1" friction="0.1"/>
  </joint>
  <joint name="knee_left_joint" type="revolute">
    <parent link="left_upper_leg_link"/>
    <child link="left_lower_leg_link"/>
    <origin rpy="0 0 0" xyz="0 -0.05 -0.21"/>
    <axis xyz="0 1 0"/>
    <limit effort="10" lower="-1.57" upper="1.57" velocity="100"/>
    <dynamics damping="0.1" friction="0.1"/>
  </joint>
  <joint name="ankle_right_joint" type="continuous">
    <parent link="right_lower_leg_link"/>
    <child link="right_wheel_link"/>
    <origin rpy="1.57 0 0" xyz="0 -0.05 -0.21"/>
    <axis xyz="0 0 1"/>
    <dynamics damping="0.1" friction="0.1"/>
    <limit effort="10" velocity="100"/>
  </joint>
  <joint name="ankle_left_joint" type="continuous">
    <parent link="left_lower_leg_link"/>
    <child link="left_wheel_link"/>
    <origin rpy="1.57 0 0" xyz="0 0.05 -0.21"/>
    <axis xyz="0 0 1"/>
    <dynamics damping="0.1" friction="0.1"/>
    <limit effort="10" velocity="100"/>
  </joint>
  <!-- IMU -->
  <joint name="IMU_joint" type="fixed">
    <axis xyz="1 0 0"/>
    <origin xyz="0 0 0.055"/>
    <parent link="base_link"/>
    <child link="IMU_link"/>
  </joint>
  <gazebo reference="base_link">
    <material>Gazebo/Green</material>
  </gazebo>
  <gazebo reference="right_upper_leg_link">
    <material>Gazebo/Red</material>
  </gazebo>
  <gazebo reference="left_upper_leg_link">
    <material>Gazebo/Red</material>
  </gazebo>
  <gazebo reference="right_lower_leg_link">
    <material>Gazebo/Red</material>
  </gazebo>
  <gazebo reference="left_lower_leg_link">
    <material>Gazebo/Red</material>
  </gazebo>
  <gazebo reference="right_wheel_link">
    <material>Gazebo/Blue</material>
  </gazebo>
  <gazebo reference="left_wheel_link">
    <material>Gazebo/Blue</material>
  </gazebo>
  <!-- Include Gazebo Plugins -->
  <gazebo>
    <plugin filename="libgazebo_ros_joint_state_publisher.so" name="gazebo_ros_joint_state_publisher">
      <update_rate>20</update_rate>
      <joint_name>hip_right_joint</joint_name>
      <joint_name>hip_left_joint</joint_name>
      <joint_name>knee_right_joint</joint_name>
      <joint_name>knee_left_joint</joint_name>
      <joint_name>ankle_right_joint</joint_name>
      <joint_name>ankle_left_joint</joint_name>
    </plugin>
  </gazebo>
  <gazebo>
    <plugin filename="libgazebo_ros_joint_pose_trajectory.so" name="gazebo_ros_joint_pose_trajectory">
      <update_rate>2</update_rate>
    </plugin>
  </gazebo>
  <gazebo>
    <plugin filename="libgazebo_ros_imu.so" name="imu_plugin">
      <alwaysOn>true</alwaysOn>
      <bodyName>base_footprint</bodyName>
      <topicName>imu</topicName>
      <serviceName>imu_service</serviceName>
      <gaussianNoise>0.0</gaussianNoise>
      <updateRate>20.0</updateRate>
    </plugin>
    <material>Gazebo/White</material>
  </gazebo>
  <ros2_control name="GazeboSystem" type="system">
    <hardware>
      <plugin>gazebo_ros2_control/GazeboSystem</plugin>
    </hardware>
    <!-- Servo joints -->
    <joint name="hip_right_joint">
      <command_interface name="position">
        <param name="min">-1.5708</param>
        <param name="max">1.5708</param>
      </command_interface>
      <state_interface name="position"/>
    </joint>
    <joint name="hip_left_joint">
      <command_interface name="position">
        <param name="min">-1.5708</param>
        <param name="max">1.5708</param>
      </command_interface>
      <state_interface name="position"/>
    </joint>
    <joint name="knee_right_joint">
      <command_interface name="position">
        <param name="min">-1.5708</param>
        <param name="max">1.5708</param>
      </command_interface>
      <state_interface name="position"/>
    </joint>
    <joint name="knee_left_joint">
      <command_interface name="position">
        <param name="min">-1.5708</param>
        <param name="max">1.5708</param>
      </command_interface>
      <state_interface name="position"/>
    </joint>
    <!-- DC joints -->
    <joint name="ankle_right_joint">
      <command_interface name="velocity">
        <param name="min">-10</param>
        <param name="max">10</param>
      </command_interface>
      <state_interface name="velocity"/>
    </joint>
    <joint name="ankle_left_joint">
      <command_interface name="velocity">
        <param name="min">-10</param>
        <param name="max">10</param>
      </command_interface>
      <state_interface name="velocity"/>
    </joint>
  </ros2_control>
  <gazebo>
    <plugin filename="libgazebo_ros2_control.so" name="gazebo_ros2_control">
      <parameters>/home/louis/Documents/PROJECTS-OF-MINE/Bipedal_Work/ros2_bipedal_ws/install/bipedal_robot_description/share/bipedal_robot_description/config/my_controllers.yaml</parameters>
    </plugin>
  </gazebo>
</robot>
