<?xml version="1.0" ?>
<!-- =================================================================================== -->
<!-- |    This document was autogenerated by xacro from bipedal_description.urdf.xacro | -->
<!-- |    EDITING THIS FILE BY HAND IS NOT RECOMMENDED                                 | -->
<!-- =================================================================================== -->
<robot name="cube_robot">
  <!-- Define base -->
  <link name="base_link">
    <inertial>
      <origin rpy="0 0 0" xyz="0 0 0"/>
      <mass value="1"/>
      <inertia ixx="0.0833333" ixy="0" ixz="0" iyy="0.0833333" iyz="0" izz="0.0833333"/>
    </inertial>
    <collision>
      <origin rpy="0 0 0" xyz="0 0 0"/>
      <geometry>
        <box size="1 1 1"/>
      </geometry>
    </collision>
    <visual>
      <origin rpy="0 0 0" xyz="0 0 0"/>
      <geometry>
        <box size="1 1 1"/>
      </geometry>
      <material name="red">
        <color rgba="0.8 0.1 0.1 1"/>
      </material>
    </visual>
  </link>
  <link name="left_leg_link">
    <inertial>
      <origin rpy="0 0 0" xyz="0 0 -0.5"/>
      <mass value="0.5"/>
      <inertia ixx="0.0138889" ixy="0" ixz="0" iyy="0.0138889" iyz="0" izz="0.0138889"/>
    </inertial>
    <collision>
      <origin rpy="0 0 0" xyz="0 0 -0.5"/>
      <geometry>
        <box size="0.5 0.5 2"/>
      </geometry>
    </collision>
    <visual>
      <origin rpy="0 0 0" xyz="0 0 -0.5"/>
      <geometry>
        <box size="0.5 0.5 2"/>
      </geometry>
      <material name="blue">
        <color rgba="0.1 0.1 0.8 1"/>
      </material>
    </visual>
  </link>
  <link name="right_leg_link">
    <inertial>
      <origin rpy="0 0 0" xyz="0 0 -0.5"/>
      <mass value="0.5"/>
      <inertia ixx="0.0138889" ixy="0" ixz="0" iyy="0.0138889" iyz="0" izz="0.0138889"/>
    </inertial>
    <collision>
      <origin rpy="0 0 0" xyz="0 0 -0.5"/>
      <geometry>
        <box size="0.5 0.5 2"/>
      </geometry>
    </collision>
    <visual>
      <origin rpy="0 0 0" xyz="0 0 -0.5"/>
      <geometry>
        <box size="0.5 0.5 2"/>
      </geometry>
      <material name="blue">
        <color rgba="0.1 0.1 0.8 1"/>
      </material>
    </visual>
  </link>
  <!-- Joint definition -->
  <joint name="left_leg_joint" type="revolute">
    <parent link="base_link"/>
    <child link="left_leg_link"/>
    <origin rpy="0 0 0" xyz="-0.75 0 0"/>
    <axis xyz="1 0 0"/>
    <limit effort="100" lower="-1.57" upper="1.57" velocity="1.0"/>
  </joint>
  <joint name="right_leg_joint" type="revolute">
    <parent link="base_link"/>
    <child link="right_leg_link"/>
    <origin rpy="0 0 0" xyz="0.75 0 0"/>
    <axis xyz="1 0 0"/>
    <limit effort="100" lower="-1.57" upper="1.57" velocity="1.0"/>
  </joint>
</robot>
