<?xml version="1.0" encoding="utf-8"?>
<!-- This URDF was automatically created by SolidWorks to URDF Exporter! Originally created by Stephen Brawner (brawner@gmail.com) 
     Commit Version: 1.6.0-4-g7f85cfe  Build Version: 1.6.7995.38578
     For more information, please see http://wiki.ros.org/sw_urdf_exporter -->
<robot
  name="bipedal.SLDASM">
  <link
    name="body">
    <inertial>
      <origin
        xyz="-0.05 -0.0171013201755109 0.0143623011241136"
        rpy="0 0 0" />
      <mass
        value="0.0861212527896542" />
      <inertia
        ixx="2.27226159456877E-05"
        ixy="3.65565093371569E-21"
        ixz="8.15930956222306E-21"
        iyy="4.09061918452724E-05"
        iyz="-4.47643903406404E-21"
        izz="2.40138972081395E-05" />
    </inertial>
    <visual>
      <origin
        xyz="0 0 0"
        rpy="0 0 0" />
      <geometry>
        <mesh
          filename="package://bipedal.SLDASM/meshes/body.STL" />
      </geometry>
      <material
        name="">
        <color
          rgba="0.792156862745098 0.819607843137255 0.933333333333333 1" />
      </material>
    </visual>
    <collision>
      <origin
        xyz="0 0 0"
        rpy="0 0 0" />
      <geometry>
        <mesh
          filename="package://bipedal.SLDASM/meshes/body.STL" />
      </geometry>
    </collision>
  </link>
  <link
    name="up_left">
    <inertial>
      <origin
        xyz="-0.0900237685274533 -0.000800737066319293 -0.0211609061395259"
        rpy="0 0 0" />
      <mass
        value="0.0414539466144867" />
      <inertia
        ixx="9.94394681372434E-06"
        ixy="1.25837919865739E-09"
        ixz="-4.75619837507004E-08"
        iyy="1.89242479102518E-05"
        iyz="-2.89847198239973E-08"
        izz="2.1810516004308E-05" />
    </inertial>
    <visual>
      <origin
        xyz="0 0 0"
        rpy="0 0 0" />
      <geometry>
        <mesh
          filename="package://bipedal.SLDASM/meshes/up_left.STL" />
      </geometry>
      <material
        name="">
        <color
          rgba="0.792156862745098 0.819607843137255 0.933333333333333 1" />
      </material>
    </visual>
    <collision>
      <origin
        xyz="0 0 0"
        rpy="0 0 0" />
      <geometry>
        <mesh
          filename="package://bipedal.SLDASM/meshes/up_left.STL" />
      </geometry>
    </collision>
  </link>
  <joint
    name="knee_left"
    type="continuous">
    <origin
      xyz="-0.0924999998882412 -0.0175000000000001 0.024"
      rpy="1.5707963267949 0.33515942695841 1.5707963267949" />
    <parent
      link="body" />
    <child
      link="up_left" />
    <axis
      xyz="0 0 1" />
  </joint>
  <link
    name="down_left">
    <inertial>
      <origin
        xyz="-0.0799579113425913 0.0178992414159899 0.0119244924872847"
        rpy="0 0 0" />
      <mass
        value="0.0398135046111743" />
      <inertia
        ixx="1.2029730942839E-05"
        ixy="-1.42843186044429E-09"
        ixz="9.47356661279306E-09"
        iyy="7.90669295312632E-06"
        iyz="6.18776778314193E-08"
        izz="1.74948658784837E-05" />
    </inertial>
    <visual>
      <origin
        xyz="0 0 0"
        rpy="0 0 0" />
      <geometry>
        <mesh
          filename="package://bipedal.SLDASM/meshes/down_left.STL" />
      </geometry>
      <material
        name="">
        <color
          rgba="0.792156862745098 0.819607843137255 0.933333333333333 1" />
      </material>
    </visual>
    <collision>
      <origin
        xyz="0 0 0"
        rpy="0 0 0" />
      <geometry>
        <mesh
          filename="package://bipedal.SLDASM/meshes/down_left.STL" />
      </geometry>
    </collision>
  </link>
  <joint
    name="ankle_left"
    type="continuous">
    <origin
      xyz="-0.101991243034601 -0.0110721156671643 -0.0429999999999999"
      rpy="-3.14159265358979 0 0.319800102224046" />
    <parent
      link="up_left" />
    <child
      link="down_left" />
    <axis
      xyz="0 0 1" />
  </joint>
  <link
    name="wheel_left">
    <inertial>
      <origin
        xyz="1.11022302462516E-16 -2.77555756156289E-17 -0.0125000000000002"
        rpy="0 0 0" />
      <mass
        value="0.0822508226617978" />
      <inertia
        ixx="2.61883192237553E-05"
        ixy="1.32348898008484E-23"
        ixz="9.84896425958825E-21"
        iyy="2.61883192237553E-05"
        iyz="-8.01589229352956E-21"
        izz="4.380884442024E-05" />
    </inertial>
    <visual>
      <origin
        xyz="0 0 0"
        rpy="0 0 0" />
      <geometry>
        <mesh
          filename="package://bipedal.SLDASM/meshes/wheel_left.STL" />
      </geometry>
      <material
        name="">
        <color
          rgba="0.792156862745098 0.819607843137255 0.933333333333333 1" />
      </material>
    </visual>
    <collision>
      <origin
        xyz="0 0 0"
        rpy="0 0 0" />
      <geometry>
        <mesh
          filename="package://bipedal.SLDASM/meshes/wheel_left.STL" />
      </geometry>
    </collision>
  </link>
  <joint
    name="pivot_left"
    type="continuous">
    <origin
      xyz="-0.085 0 0.0230000000000001"
      rpy="-3.14159265358979 0 -0.00630300427140065" />
    <parent
      link="down_left" />
    <child
      link="wheel_left" />
    <axis
      xyz="0 0 1" />
  </joint>
  <link
    name="up_right">
    <inertial>
      <origin
        xyz="-0.0900237685274533 0.000655996944268489 -0.0136609060277669"
        rpy="0 0 0" />
      <mass
        value="0.0414539466144867" />
      <inertia
        ixx="9.94394681372434E-06"
        ixy="1.25837919867369E-09"
        ixz="-4.75619837506984E-08"
        iyy="1.89242479102518E-05"
        iyz="2.90123580340712E-08"
        izz="2.1810516004308E-05" />
    </inertial>
    <visual>
      <origin
        xyz="0 0 0"
        rpy="0 0 0" />
      <geometry>
        <mesh
          filename="package://bipedal.SLDASM/meshes/up_right.STL" />
      </geometry>
      <material
        name="">
        <color
          rgba="0.792156862745098 0.819607843137255 0.933333333333333 1" />
      </material>
    </visual>
    <collision>
      <origin
        xyz="0 0 0"
        rpy="0 0 0" />
      <geometry>
        <mesh
          filename="package://bipedal.SLDASM/meshes/up_right.STL" />
      </geometry>
    </collision>
  </link>
  <joint
    name="knee_right"
    type="continuous">
    <origin
      xyz="0 -0.0175 0.024"
      rpy="-1.5707963267949 -0.0656950877658922 1.5707963267949" />
    <parent
      link="body" />
    <child
      link="up_right" />
    <axis
      xyz="0 0 1" />
  </joint>
  <link
    name="down_right">
    <inertial>
      <origin
        xyz="-0.0799579114901579 -0.0179006865343754 0.0119244925618341"
        rpy="0 0 0" />
      <mass
        value="0.0398135042766036" />
      <inertia
        ixx="1.20297312082357E-05"
        ixy="-1.42747387731231E-09"
        ixz="9.47354408868546E-09"
        iyy="7.9066923303417E-06"
        iyz="-6.18187584081892E-08"
        izz="1.74948655222408E-05" />
    </inertial>
    <visual>
      <origin
        xyz="0 0 0"
        rpy="0 0 0" />
      <geometry>
        <mesh
          filename="package://bipedal.SLDASM/meshes/down_right.STL" />
      </geometry>
      <material
        name="">
        <color
          rgba="0.792156862745098 0.819607843137255 0.933333333333333 1" />
      </material>
    </visual>
    <collision>
      <origin
        xyz="0 0 0"
        rpy="0 0 0" />
      <geometry>
        <mesh
          filename="package://bipedal.SLDASM/meshes/down_right.STL" />
      </geometry>
    </collision>
  </link>
  <joint
    name="ankle_right"
    type="continuous">
    <origin
      xyz="-0.101991243034601 0.0109278845340023 -0.0354999998882412"
      rpy="-3.14159265358979 0 0.111919198091748" />
    <parent
      link="up_right" />
    <child
      link="down_right" />
    <axis
      xyz="0 0 1" />
  </joint>
  <link
    name="wheel_right">
    <inertial>
      <origin
        xyz="-6.64399091299117E-16 -2.77555756156289E-17 0.0125000000000001"
        rpy="0 0 0" />
      <mass
        value="0.0822508226617978" />
      <inertia
        ixx="2.61883192237553E-05"
        ixy="4.2351647362715E-22"
        ixz="1.49823480789765E-21"
        iyy="2.61883192237553E-05"
        iyz="3.43388561364539E-21"
        izz="4.380884442024E-05" />
    </inertial>
    <visual>
      <origin
        xyz="0 0 0"
        rpy="0 0 0" />
      <geometry>
        <mesh
          filename="package://bipedal.SLDASM/meshes/wheel_right.STL" />
      </geometry>
      <material
        name="">
        <color
          rgba="0.792156862745098 0.819607843137255 0.933333333333333 1" />
      </material>
    </visual>
    <collision>
      <origin
        xyz="0 0 0"
        rpy="0 0 0" />
      <geometry>
        <mesh
          filename="package://bipedal.SLDASM/meshes/wheel_right.STL" />
      </geometry>
    </collision>
  </link>
  <joint
    name="pivot_right"
    type="continuous">
    <origin
      xyz="-0.0849999999999999 0 0.0230000000000005"
      rpy="0 0 1.53407199661008" />
    <parent
      link="down_right" />
    <child
      link="wheel_right" />
    <axis
      xyz="0 0 1" />
  </joint>
</robot>